Workbook

Sheet Outreach Tracker
A1: DataCenterConsulting.org — Grid-Safe AI Data Center Power Architecture Advisory Campaign
A2: Stakeholder Outreach Tracking Matrix
A3: Category | B3: Entity | C3: Contact | D3: Email | E3: Phone | F3: Priority | G3: Status | H3: Outreach Phase | I3: Letter Sent | J3: Email Sent | K3: Meeting Scheduled | L3: Next Step | M3: Notes | N3: Last Updated | O3: Owner
A4: Federal Government / DOE | B4: DOE Office of Electricity — Grid Modernization Initiative | C4: Program Director (TBD) | D4: TBD | E4: TBD | F4: High | G4: Not Started | H4: Phase 4 (Week 4-6) | I4: No | J4: No | K4: No | L4: Finalize internal alignment before outreach | M4: SPARK program $1.9B — concept papers due Apr 2; full apps May 20 2026. Align outreach with GRIP/SPARK framework. Key program: Grid Resilience and Innovation Partnerships. | N4: 46141 | O4: DataCenterConsulting.org
A5: National Laboratories | B5: NLR / NREL — ARIES Platform | C5: Andrew Hudgins (ARIES Lab Program Manager) | D5: TBD | E5: TBD | F5: High | G5: Not Started | H5: Phase 2 (Week 2-3) | I5: No | J5: No | K5: No | L5: Draft partnership proposal referencing ON.energy validation at Flatirons | M5: ARIES at Flatirons Campus — 20MW load simulator; 7MW grid simulator; 13.2kV. ON.energy AI UPS already deployed and validated here. | N5: 46141 | O5: DataCenterConsulting.org
A6: National Laboratories | B6: PNNL — Grid Modernization Group | C6: Division Director (TBD) | D6: TBD | E6: TBD | F6: Medium | G6: Not Started | H6: Phase 2 (Week 2-3) | I6: No | J6: No | K6: No | L6: Identify correct contact via GMLC network | M6: GMLC member lab. Strong in grid analytics and transmission modeling. | N6: 46141 | O6: DataCenterConsulting.org
A7: MV AI-UPS Vendors | B7: ON.energy — Data Center Division | C7: Dax Kepshire (President DC Division) | D7: TBD | E7: TBD | F7: High | G7: Not Started | H7: Phase 3 (Week 3-4) | I7: No | J7: No | K7: No | L7: Send introductory letter and request evaluation partnership call | M7: AI UPS 3.2MW/module; patent-pending; MV; validated at NLR ARIES/Flatirons. Deployed with hyperscalers. Co-develop case study opportunity. | N7: 46141 | O7: DataCenterConsulting.org
A8: MV AI-UPS Vendors | B8: Eaton — Data Center Segment | C8: JP Buzzell (VP / Chief Data Center Architect) | D8: TBD | E8: TBD | F8: High | G8: Not Started | H8: Phase 3 (Week 3-4) | I8: No | J8: No | K8: No | L8: Send introductory letter referencing PXQ SSO detection | M8: Grid-to-chip strategy. PXQ event analysis for SSO detection. Partnership with Siemens Energy. Fibrebond acquisition. Evaluate MV power quality solutions vs AI UPS architectures. | N8: 46141 | O8: DataCenterConsulting.org
A9: Local Utility | B9: Local Utility — Interconnection Planning (placeholder) | C9: Director of Large Customer Services (TBD) | D9: TBD | E9: TBD | F9: Medium | G9: Not Started | H9: Phase 5 (Week 5-7) | I9: No | J9: No | K9: No | L9: Identify correct utility and contact based on builder site location | M9: Approach with full package after DOE/lab/vendor context established. Emphasize grid-safe architecture as utility benefit. Reference SPARK alignment. | N9: 46141 | O9: DataCenterConsulting.org
A10: Retained Builder Client | B10: [Builder Partner — Name] | C10: [Primary Contact] | D10: TBD | E10: TBD | F10: Critical | G10: In Progress | H10: Phase 1 (Week 1-2) | I10: N/A | J10: N/A | K10: Yes | L10: Finalize site specs; review NDA templates; approve outreach messaging | M10: Internal alignment is prerequisite for all external outreach. Needs to provide: site location; power requirements; timeline; campus master plan; technical specs for interconnection. | N10: 46141 | O10: DataCenterConsulting.org
A11: Landowners / Property Owners | B11: [Landowner Name — Power-Adjacent Property] | C11: [Property Owner] | D11: TBD | E11: TBD | F11: High | G11: Not Started | H11: Phase 1b (Week 1-2) | I11: No | J11: No | K11: No | L11: Launch land-data capture platform; begin collecting property submissions | M11: Platform captures objective data (acreage, zoning, distance to substation/transmission, infrastructure, road access, water, environmental status) and subjective data (timeline, price expectations, sell vs. lease preference). Target properties near grid substations, power plants, hydro, nuclear. Land values $15k-$50k/acre vs traditional $10-$15k/acre. | N11: 46141 | O11: DataCenterConsulting.org
A12: Municipal / Local Government | B12: City of [City] — Mayor's Office | C12: The Honorable [Mayor Name] | D12: TBD | E12: TBD | F12: High | G12: Not Started | H12: Phase 5 (Week 5-7) | I12: No | J12: No | K12: No | L12: Identify target municipality based on site location; request meeting with mayor and economic development staff | M12: Frame as economic development opportunity: jobs, tax base, infrastructure investment, DOE SPARK alignment. Address concerns proactively: grid-safe architecture, water minimization, noise mitigation. Community benefit agreements. | N12: 46141 | O12: DataCenterConsulting.org
A13: Municipal / Local Government | B13: [City] — Planning and Zoning Department | C13: Director of Planning (TBD) | D13: TBD | E13: TBD | F13: Medium | G13: Not Started | H13: Phase 5 (Week 5-7) | I13: No | J13: No | K13: No | L13: Request pre-application conference for data center campus zoning | M13: Understand zoning requirements, conditional use permits, setback requirements, noise ordinances. Engage early to avoid surprises. | N13: 46141 | O13: DataCenterConsulting.org
A14: Finance / Capital Partners | B14: [Infrastructure Fund / REIT / Project Finance Bank] | C14: Managing Director, Infrastructure Investments (TBD) | D14: TBD | E14: TBD | F14: High | G14: Not Started | H14: Phase 6 (Week 6-8) | I14: No | J14: No | K14: No | L14: Prepare investment thesis deck; approach with full validation package (DOE + lab + vendor) | M14: Investment thesis: AI compute demand growing faster than grid capacity creates premium for validated grid-safe campuses. DataCenterConsulting.org de-risks via independent technical validation, vendor-neutral evaluation, utility advisory, and proprietary land-data registry. Also consider DOE Loan Programs Office (LPO). | N14: 46141 | O14: DataCenterConsulting.org
A15: AI / Compute Demand Partners | B15: [Hyperscaler / AI Company] — Infrastructure Team | C15: VP of Infrastructure / DC Strategy (TBD) | D15: TBD | E15: TBD | F15: Medium | G15: Not Started | H15: Phase 7 (Week 7-9) | I15: No | J15: No | K15: No | L15: Approach with validated campus concept; propose informational exchange on compute requirements | M15: Tenants benefit from superior power quality (reduced GPU transient impact), higher availability (grid-safe ride-through), and accelerated interconnection. Understand their minimum power quality specs, deployment timeline pressure, and site evaluation criteria. | N15: 46141 | O15: DataCenterConsulting.org
... A20: Industry Associations / Standards Bodies | B20: [Data Center Coalition / ASHRAE TC 9.9 / IEEE PES / Uptime Institute] | C20: Executive Director / Membership Committee (TBD) | D20: TBD | E20: TBD | F20: Low | G20: Not Started | H20: Phase 9 (Week 8-12) | I20: No | J20: No | K20: No | L20: Apply for membership; identify relevant working groups; propose research contribution | M20: Participate in IEEE 1547 revisions, ASHRAE thermal guidelines for AI workloads, DC power architecture standards. Contribute research from national lab validation. Frame as industry advancement, not self-promotion. | N20: 46141 | O20: DataCenterConsulting.org

Sheet Dashboard
A1: Campaign Dashboard — DataCenterConsulting.org (14 Stakeholder Categories)
A2: Stakeholder Outreach Summary & Key Dates
A4: OVERVIEW METRICS | E4: OUTREACH PHASE TIMELINE
A5: Metric | B5: Count | C5: % of Total | E5: Phase | F5: Timeline | G5: Entities | H5: Status
A6: Total Entities | B6: =COUNTA('Outreach Tracker'!B4:B100) | E6: Phase 1 — Internal Alignment | F6: Week 1-2 | G6: =COUNTIF('Outreach Tracker'!H$4:H$100,"Phase 1*") | H6: Active
A7: Letters Sent | B7: =COUNTIF('Outreach Tracker'!I4:I100,"Yes") | C7: =IF(B6=0,0,B7/B6) | E7: Phase 1b — Landowner Platform | F7: Week 1-2 | G7: =COUNTIF('Outreach Tracker'!H$4:H$100,"Phase 1b*") | H7: Upcoming
A8: Emails Sent | B8: =COUNTIF('Outreach Tracker'!J4:J100,"Yes") | C8: =IF(B6=0,0,B8/B6) | E8: Phase 2 — National Labs | F8: Week 2-3 | G8: =COUNTIF('Outreach Tracker'!H$4:H$100,"Phase 2*") | H8: Upcoming
A9: Meetings Scheduled | B9: =COUNTIF('Outreach Tracker'!K4:K100,"Yes") | C9: =IF(B6=0,0,B9/B6) | E9: Phase 3 — MV AI-UPS Vendors | F9: Week 3-4 | G9: =COUNTIF('Outreach Tracker'!H$4:H$100,"Phase 3*") | H9: Upcoming
E10: Phase 4 — Federal / DOE | F10: Week 4-6 | G10: =COUNTIF('Outreach Tracker'!H$4:H$100,"Phase 4*") | H10: Upcoming
E11: Phase 5 — Local Utility + Municipal | F11: Week 5-7 | G11: =COUNTIF('Outreach Tracker'!H$4:H$100,"Phase 5*") | H11: Upcoming
E12: Phase 6 — Finance/Capital | F12: Week 6-8 | G12: =COUNTIF('Outreach Tracker'!H$4:H$100,"Phase 6*") | H12: Upcoming
E13: Phase 7 — AI/Compute Demand | F13: Week 7-9 | G13: =COUNTIF('Outreach Tracker'!H$4:H$100,"Phase 7*") | H13: Upcoming
E14: Phase 8 — Environmental | F14: Week 6-10 | G14: =COUNTIF('Outreach Tracker'!H$4:H$100,"Phase 8*") | H14: Upcoming
E15: Phase 9 — Media + Associations | F15: Week 8-12 | G15: =COUNTIF('Outreach Tracker'!H$4:H$100,"Phase 9*") | H15: Upcoming
E16: Phase 10 — Community | F16: Week 8-12 | G16: =COUNTIF('Outreach Tracker'!H$4:H$100,"Phase 10*") | H16: Upcoming
A18: STATUS BREAKDOWN | E18: KEY DATES & MILESTONES
A19: Status | B19: Count | C19: % of Total | E19: Milestone | F19: Date | G19: Status | H19: Notes
A20: Not Started | B20: =COUNTIF('Outreach Tracker'!G$4:G$100,A20) | C20: =IF(B$6=0,0,B20/B$6) | E20: SPARK Concept Paper Deadline | F20: 46114 | G20: PASSED | H20: Deadline has passed
A21: In Progress | B21: =COUNTIF('Outreach Tracker'!G$4:G$100,A21) | C21: =IF(B$6=0,0,B21/B$6) | E21: SPARK Full Application Deadline | F21: 46162 | G21: UPCOMING | H21: 21 days remaining as of Apr 29
A22: Complete | B22: =COUNTIF('Outreach Tracker'!G$4:G$100,A22) | C22: =IF(B$6=0,0,B22/B$6) | E22: SPARK Selection Notification | F22: 46235 | G22: FUTURE | H22: Estimated Aug 2026
A23: On Hold | B23: =COUNTIF('Outreach Tracker'!G$4:G$100,A23) | C23: =IF(B$6=0,0,B23/B$6) | E23: SPARK Anticipated Award (Start) | F23: 46296 | G23: FUTURE | H23: Estimated Oct 2026
E24: SPARK Anticipated Award (End) | F24: 46418 | G24: FUTURE | H24: Estimated Jan 2027
A25: PRIORITY BREAKDOWN | E25: Phase 1 Target Completion | F25: 46155 | G25: IN PROGRESS | H25: Internal alignment with builder partner
A26: Priority | B26: Count | C26: % of Total | E26: Phase 2 Target Start | F26: 46148 | G26: PLANNED | H26: National Labs outreach begins
A27: Critical | B27: =COUNTIF('Outreach Tracker'!F$4:F$100,A27) | C27: =IF(B$6=0,0,B27/B$6) | E27: Phase 3 Target Start | F27: 46155 | G27: PLANNED | H27: Vendor outreach begins
A28: High | B28: =COUNTIF('Outreach Tracker'!F$4:F$100,A28) | C28: =IF(B$6=0,0,B28/B$6) | E28: Phase 4 Target Start | F28: 46162 | G28: PLANNED | H28: Federal/DOE outreach begins
A29: Medium | B29: =COUNTIF('Outreach Tracker'!F$4:F$100,A29) | C29: =IF(B$6=0,0,B29/B$6) | E29: Phase 5 Target Start | F29: 46169 | G29: PLANNED | H29: Utility outreach begins
A30: Low | B30: =COUNTIF('Outreach Tracker'!F$4:F$100,A30) | C30: =IF(B$6=0,0,B30/B$6) | E30: Land-Data Platform Launch Target | F30: 46148 | G30: PLANNED | H30: Land-data capture platform launch
E31: Phase 6 Target Start (Finance) | F31: 46176 | G31: PLANNED | H31: Finance/Capital outreach begins
A32: CATEGORY BREAKDOWN | E32: Phase 7 Target Start (AI/Compute) | F32: 46183 | G32: PLANNED | H32: AI/Compute demand outreach begins
A33: Category | B33: Count | C33: % of Total | E33: White Paper Draft Target | F33: 46204 | G33: PLANNED | H33: Grid-Safe AI Compute white paper
A34: Federal Government / DOE | B34: =COUNTIF('Outreach Tracker'!A$4:A$100,A34) | C34: =IF(B$6=0,0,B34/B$6)
A35: National Laboratories | B35: =COUNTIF('Outreach Tracker'!A$4:A$100,A35) | C35: =IF(B$6=0,0,B35/B$6)
A36: MV AI-UPS Vendors | B36: =COUNTIF('Outreach Tracker'!A$4:A$100,A36) | C36: =IF(B$6=0,0,B36/B$6)
A37: Local Utility | B37: =COUNTIF('Outreach Tracker'!A$4:A$100,A37) | C37: =IF(B$6=0,0,B37/B$6)
A38: Retained Builder Client | B38: =COUNTIF('Outreach Tracker'!A$4:A$100,A38) | C38: =IF(B$6=0,0,B38/B$6)
A39: Landowners / Property Owners | B39: =COUNTIF('Outreach Tracker'!A$4:A$100,A39) | C39: =IF(B$6=0,0,B39/B$6)
A40: Municipal / Local Government | B40: =COUNTIF('Outreach Tracker'!A$4:A$100,A40) | C40: =IF(B$6=0,0,B40/B$6)
A41: Finance / Capital Partners | B41: =COUNTIF('Outreach Tracker'!A$4:A$100,A41) | C41: =IF(B$6=0,0,B41/B$6)
A42: AI / Compute Demand Partners | B42: =COUNTIF('Outreach Tracker'!A$4:A$100,A42) | C42: =IF(B$6=0,0,B42/B$6)
...
